Workbook

Sheet Cleaned Inventory Data
A1: Transaction ID | B1: Transaction Date | C1: Product ID | D1: Transaction Type | E1: Quantity | F1: Stock Movement | G1: Warehouse | H1: Supplier | I1: Supplier Country | J1: Unit Cost | K1: Unit Price | L1: Purchase Order | M1: Inventory Value | N1: Sale Value | O1: Purchase Value
A2: INV-01067 | B2: 45658 | C2: P008 | D2: Sale | E2: -2 | F2: =E2 -> -2 | G2: Central Warehouse | H2: BrightHome | I2: China | J2: 13.5 | K2: 24 | M2: =ABS(E2)*J2 -> 27 | N2: =IF(Table1[[#This Row],[Transaction Type]]="Sale",ABS(E2)*K2,0) -> 48 | O2: =IF(Table1[[#This Row],[Transaction Type]]="Purchase",E2*J2,0) -> 0
A3: INV-00742 | B3: 45658 | C3: P011 | D3: Sale | E3: -8 | F3: =E3 -> -8 | G3: South Warehouse | H3: PaperMate | I3: Germany | J3: 2.6 | K3: 5.5 | M3: =ABS(E3)*J3 -> 20.8 | N3: =IF(Table1[[#This Row],[Transaction Type]]="Sale",ABS(E3)*K3,0) -> 44 | O3: =IF(Table1[[#This Row],[Transaction Type]]="Purchase",E3*J3,0) -> 0
A4: INV-00128 | B4: 45658 | C4: P028 | D4: Sale | E4: -11 | F4: =E4 -> -11 | G4: North Warehouse | H4: PackRight | I4: Poland | J4: 3 | K4: 7 | M4: =ABS(E4)*J4 -> 33 | N4: =IF(Table1[[#This Row],[Transaction Type]]="Sale",ABS(E4)*K4,0) -> 77 | O4: =IF(Table1[[#This Row],[Transaction Type]]="Purchase",E4*J4,0) -> 0
A5: INV-01061 | B5: 45659 | C5: P028 | D5: Sale | E5: -12 | F5: =E5 -> -12 | G5: Central Warehouse | H5: PackRight | I5: Poland | J5: 3 | K5: 7 | M5: =ABS(E5)*J5 -> 36 | N5: =IF(Table1[[#This Row],[Transaction Type]]="Sale",ABS(E5)*K5,0) -> 84 | O5: =IF(Table1[[#This Row],[Transaction Type]]="Purchase",E5*J5,0) -> 0
A6: INV-01015 | B6: 45659 | C6: P023 | D6: Sale | E6: -11 | F6: =E6 -> -11 | G6: North Warehouse | H6: DeskWorks | I6: China | J6: 8.8 | K6: 17 | M6: =ABS(E6)*J6 -> 96.8 | N6: =IF(Table1[[#This Row],[Transaction Type]]="Sale",ABS(E6)*K6,0) -> 187 | O6: =IF(Table1[[#This Row],[Transaction Type]]="Purchase",E6*J6,0) -> 0
A7: INV-00334 | B7: 45659 | C7: P004 | D7: Sale | E7: -14 | F7: =E7 -> -14 | G7: South Warehouse | H7: SoundMax | I7: Vietnam | J7: 20 | K7: 35 | M7: =ABS(E7)*J7 -> 280 | N7: =IF(Table1[[#This Row],[Transaction Type]]="Sale",ABS(E7)*K7,0) -> 490 | O7: =IF(Table1[[#This Row],[Transaction Type]]="Purchase",E7*J7,0) -> 0
A8: INV-01350 | B8: 45659 | C8: P001 | D8: Sale | E8: -14 | F8: =E8 -> -14 | G8: North Warehouse | H8: TechGear | I8: China | J8: 7.2 | K8: 12.5 | M8: =ABS(E8)*J8 -> 100.8 | N8: =IF(Table1[[#This Row],[Transaction Type]]="Sale",ABS(E8)*K8,0) -> 175 | O8: =IF(Table1[[#This Row],[Transaction Type]]="Purchase",E8*J8,0) -> 0
A9: INV-00089 | B9: 45659 | C9: P028 | D9: Sale | E9: -1 | F9: =E9 -> -1 | G9: North Warehouse | H9: PackRight | I9: Poland | J9: 3 | K9: 7 | M9: =ABS(E9)*J9 -> 3 | N9: =IF(Table1[[#This Row],[Transaction Type]]="Sale",ABS(E9)*K9,0) -> 7 | O9: =IF(Table1[[#This Row],[Transaction Type]]="Purchase",E9*J9,0) -> 0
A10: INV-00898 | B10: 45660 | C10: P028 | D10: Purchase | E10: 63 | F10: =E10 -> 63 | G10: Central Warehouse | H10: PackRight | I10: Poland | J10: 3 | K10: 7 | L10: PO-58135 | M10: =ABS(E10)*J10 -> 189 | N10: =IF(Table1[[#This Row],[Transaction Type]]="Sale",ABS(E10)*K10,0) -> 0 | O10: =IF(Table1[[#This Row],[Transaction Type]]="Purchase",E10*J10,0) -> 189
A11: INV-00725 | B11: 45661 | C11: P018 | D11: Sale | E11: -15 | F11: =E11 -> -15 | G11: Central Warehouse | H11: DataStore | I11: South Korea | J11: 5.2 | K11: 11 | M11: =ABS(E11)*J11 -> 78 | N11: =IF(Table1[[#This Row],[Transaction Type]]="Sale",ABS(E11)*K11,0) -> 165 | O11: =IF(Table1[[#This Row],[Transaction Type]]="Purchase",E11*J11,0) -> 0
A12: INV-00503 | B12: 45661 | C12: P011 | D12: Sale | E12: -2 | F12: =E12 -> -2 | G12: Central Warehouse | H12: PaperMate | I12: Germany | J12: 2.6 | K12: 5.5 | M12: =ABS(E12)*J12 -> 5.2 | N12: =IF(Table1[[#This Row],[Transaction Type]]="Sale",ABS(E12)*K12,0) -> 11 | O12: =IF(Table1[[#This Row],[Transaction Type]]="Purchase",E12*J12,0) -> 0
A13: INV-00781 | B13: 45661 | C13: P022 | D13: Purchase | E13: 35 | F13: =E13 -> 35 | G13: North Warehouse | H13: HydroLife | I13: Germany | J13: 8.5 | K13: 18 | L13: PO-72744 | M13: =ABS(E13)*J13 -> 297.5 | N13: =IF(Table1[[#This Row],[Transaction Type]]="Sale",ABS(E13)*K13,0) -> 0 | O13: =IF(Table1[[#This Row],[Transaction Type]]="Purchase",E13*J13,0) -> 297.5
A14: INV-00421 | B14: 45662 | C14: P025 | D14: Sale | E14: -11 | F14: =E14 -> -11 | G14: Central Warehouse | H14: PaperMate | I14: Germany | J14: 5.5 | K14: 12 | M14: =ABS(E14)*J14 -> 60.5 | N14: =IF(Table1[[#This Row],[Transaction Type]]="Sale",ABS(E14)*K14,0) -> 132 | O14: =IF(Table1[[#This Row],[Transaction Type]]="Purchase",E14*J14,0) -> 0
A15: INV-01652 | B15: 45663 | C15: P011 | D15: Sale | E15: -3 | F15: =E15 -> -3 | G15: South Warehouse | H15: PaperMate | I15: Germany | J15: 2.6 | K15: 5.5 | M15: =ABS(E15)*J15 -> 7.8 | N15: =IF(Table1[[#This Row],[Transaction Type]]="Sale",ABS(E15)*K15,0) -> 16.5 | O15: =IF(Table1[[#This Row],[Transaction Type]]="Purchase",E15*J15,0) -> 0
A16: INV-01010 | B16: 45663 | C16: P016 | D16: Sale | E16: -7 | F16: =E16 -> -7 | G16: Central Warehouse | H16: ConnectX | I16: China | J16: 4.2 | K16: 10 | M16: =ABS(E16)*J16 -> 29.4 | N16: =IF(Table1[[#This Row],[Transaction Type]]="Sale",ABS(E16)*K16,0) -> 70 | O16: =IF(Table1[[#This Row],[Transaction Type]]="Purchase",E16*J16,0) -> 0
A17: INV-01438 | B17: 45664 | C17: P023 | D17: Adjustment | E17: -11 | F17: =E17 -> -11 | G17: Central Warehouse | H17: DeskWorks | I17: China | J17: 8.8 | K17: 17 | M17: =ABS(E17)*J17 -> 96.8 | N17: =IF(Table1[[#This Row],[Transaction Type]]="Sale",ABS(E17)*K17,0) -> 0 | O17: =IF(Table1[[#This Row],[Transaction Type]]="Purchase",E17*J17,0) -> 0
A18: INV-01604 | B18: 45664 | C18: P012 | D18: Purchase | E18: 56 | F18: =E18 -> 56 | G18: Central Warehouse | H18: WriteWell | I18: France | J18: 3.4 | K18: 8 | L18: PO-96274 | M18: =ABS(E18)*J18 -> 190.4 | N18: =IF(Table1[[#This Row],[Transaction Type]]="Sale",ABS(E18)*K18,0) -> 0 | O18: =IF(Table1[[#This Row],[Transaction Type]]="Purchase",E18*J18,0) -> 190.4
A19: INV-01592 | B19: 45664 | C19: P030 | D19: Return | E19: 1 | F19: =E19 -> 1 | G19: Central Warehouse | H19: StoreMax | I19: Germany | J19: 11 | K19: 22 | M19: =ABS(E19)*J19 -> 11 | N19: =IF(Table1[[#This Row],[Transaction Type]]="Sale",ABS(E19)*K19,0) -> 0 | O19: =IF(Table1[[#This Row],[Transaction Type]]="Purchase",E19*J19,0) -> 0
A20: INV-00581 | B20: 45664 | C20: P015 | D20: Sale | E20: -2 | F20: =E20 -> -2 | G20: North Warehouse | H20: VoltPro | I20: China | J20: 23 | K20: 38 | M20: =ABS(E20)*J20 -> 46 | N20: =IF(Table1[[#This Row],[Transaction Type]]="Sale",ABS(E20)*K20,0) -> 76 | O20: =IF(Table1[[#This Row],[Transaction Type]]="Purchase",E20*J20,0) -> 0
A21: INV-01056 | B21: 45664 | C21: P012 | D21: Sale | E21: -11 | F21: =E21 -> -11 | G21: South Warehouse | H21: WriteWell | I21: France | J21: 3.4 | K21: 8 | M21: =ABS(E21)*J21 -> 37.4 | N21: =IF(Table1[[#This Row],[Transaction Type]]="Sale",ABS(E21)*K21,0) -> 88 | O21: =IF(Table1[[#This Row],[Transaction Type]]="Purchase",E21*J21,0) -> 0
A22: INV-01732 | B22: 45664 | C22: P020 | D22: Sale | E22: -15 | F22: =E22 -> -15 | G22: North Warehouse | H22: PrintTech | I22: Japan | J22: 30 | K22: 48 | M22: =ABS(E22)*J22 -> 450 | N22: =IF(Table1[[#This Row],[Transaction Type]]="Sale",ABS(E22)*K22,0) -> 720 | O22: =IF(Table1[[#This Row],[Transaction Type]]="Purchase",E22*J22,0) -> 0
A23: INV-01677 | B23: 45665 | C23: P002 | D23: Adjustment | E23: -8 | F23: =E23 -> -8 | G23: Central Warehouse | H23: KeyPro | I23: China | J23: 25 | K23: 42 | M23: =ABS(E23)*J23 -> 200 | N23: =IF(Table1[[#This Row],[Transaction Type]]="Sale",ABS(E23)*K23,0) -> 0 | O23: =IF(Table1[[#This Row],[Transaction Type]]="Purchase",E23*J23,0) -> 0
A24: INV-00341 | B24: 45665 | C24: P016 | D24: Sale | E24: -15 | F24: =E24 -> -15 | G24: North Warehouse | H24: ConnectX | I24: China | J24: 4.2 | K24: 10 | M24: =ABS(E24)*J24 -> 63 | N24: =IF(Table1[[#This Row],[Transaction Type]]="Sale",ABS(E24)*K24,0) -> 150 | O24: =IF(Table1[[#This Row],[Transaction Type]]="Purchase",E24*J24,0) -> 0
A25: INV-01128 | B25: 45666 | C25: P013 | D25: Adjustment | E25: 3 | F25: =E25 -> 3 | G25: Central Warehouse | H25: DeskWorks | I25: China | J25: 8 | K25: 15 | M25: =ABS(E25)*J25 -> 24 | N25: =IF(Table1[[#This Row],[Transaction Type]]="Sale",ABS(E25)*K25,0) -> 0 | O25: =IF(Table1[[#This Row],[Transaction Type]]="Purchase",E25*J25,0) -> 0
A26: INV-01691 | B26: 45666 | C26: P006 | D26: Purchase | E26: 29 | F26: =E26 -> 29 | G26: Central Warehouse | H26: ViewPlus | I26: South Korea | J26: 130 | K26: 185 | L26: PO-10319 | M26: =ABS(E26)*J26 -> 3770 | N26: =IF(Table1[[#This Row],[Transaction Type]]="Sale",ABS(E26)*K26,0) -> 0 | O26: =IF(Table1[[#This Row],[Transaction Type]]="Purchase",E26*J26,0) -> 3770
A27: INV-00297 | B27: 45666 | C27: P024 | D27: Sale | E27: -8 | F27: =E27 -> -8 | G27: Central Warehouse | H27: CalcPlus | I27: China | J27: 6 | K27: 14 | M27: =ABS(E27)*J27 -> 48 | N27: =IF(Table1[[#This Row],[Transaction Type]]="Sale",ABS(E27)*K27,0) -> 112 | O27: =IF(Table1[[#This Row],[Transaction Type]]="Purchase",E27*J27,0) -> 0
A28: INV-00931 | B28: 45667 | C28: P004 | D28: Sale | E28: -5 | F28: =E28 -> -5 | G28: Central Warehouse | H28: SoundMax | I28: Vietnam | J28: 20 | K28: 35 | M28: =ABS(E28)*J28 -> 100 | N28: =IF(Table1[[#This Row],[Transaction Type]]="Sale",ABS(E28)*K28,0) -> 175 | O28: =IF(Table1[[#This Row],[Transaction Type]]="Purchase",E28*J28,0) -> 0
A29: INV-00133 | B29: 45667 | C29: P004 | D29: Sale | E29: -11 | F29: =E29 -> -11 | G29: South Warehouse | H29: SoundMax | I29: Vietnam | J29: 20 | K29: 35 | M29: =ABS(E29)*J29 -> 220 | N29: =IF(Table1[[#This Row],[Transaction Type]]="Sale",ABS(E29)*K29,0) -> 385 | O29: =IF(Table1[[#This Row],[Transaction Type]]="Purchase",E29*J29,0) -> 0
A30: INV-00090 | B30: 45667 | C30: P016 | D30: Adjustment | E30: -8 | F30: =E30 -> -8 | G30: South Warehouse | H30: ConnectX | I30: China | J30: 4.2 | K30: 10 | M30: =ABS(E30)*J30 -> 33.6 | N30: =IF(Table1[[#This Row],[Transaction Type]]="Sale",ABS(E30)*K30,0) -> 0 | O30: =IF(Table1[[#This Row],[Transaction Type]]="Purchase",E30*J30,0) -> 0
A31: INV-00456 | B31: 45668 | C31: P016 | D31: Sale | E31: -13 | F31: =E31 -> -13 | G31: Central Warehouse | H31: ConnectX | I31: China | J31: 4.2 | K31: 10 | M31: =ABS(E31)*J31 -> 54.6 | N31: =IF(Table1[[#This Row],[Transaction Type]]="Sale",ABS(E31)*K31,0) -> 130 | O31: =IF(Table1[[#This Row],[Transaction Type]]="Purchase",E31*J31,0) -> 0
A32: INV-01711 | B32: 45668 | C32: P005 | D32: Purchase | E32: 22 | F32: =E32 -> 22 | G32: South Warehouse | H32: VisionTech | I32: China | J32: 18.5 | K32: 31 | L32: PO-54078 | M32: =ABS(E32)*J32 -> 407 | N32: =IF(Table1[[#This Row],[Transaction Type]]="Sale",ABS(E32)*K32,0) -> 0 | O32: =IF(Table1[[#This Row],[Transaction Type]]="Purchase",E32*J32,0) -> 407
A33: INV-01708 | B33: 45669 | C33: P007 | D33: Sale | E33: -14 | F33: =E33 -> -14 | G33: North Warehouse | H33: DeskWorks | I33: China | J33: 16 | K33: 29 | M33: =ABS(E33)*J33 -> 224 | N33: =IF(Table1[[#This Row],[Transaction Type]]="Sale",ABS(E33)*K33,0) -> 406 | O33: =IF(Table1[[#This Row],[Transaction Type]]="Purchase",E33*J33,0) -> 0
A34: INV-01116 | B34: 45669 | C34: P018 | D34: Sale | E34: -1 | F34: =E34 -> -1 | G34: South Warehouse | H34: DataStore | I34: South Korea | J34: 5.2 | K34: 11 | M34: =ABS(E34)*J34 -> 5.2 | N34: =IF(Table1[[#This Row],[Transaction Type]]="Sale",ABS(E34)*K34,0) -> 11 | O34: =IF(Table1[[#This Row],[Transaction Type]]="Purchase",E34*J34,0) -> 0
A35: INV-01543 | B35: 45669 | C35: P018 | D35: Sale | E35: -9 | F35: =E35 -> -9 | G35: South Warehouse | H35: DataStore | I35: South Korea | J35: 5.2 | K35: 11 | M35: =ABS(E35)*J35 -> 46.8 | N35: =IF(Table1[[#This Row],[Transaction Type]]="Sale",ABS(E35)*K35,0) -> 99 | O35: =IF(Table1[[#This Row],[Transaction Type]]="Purchase",E35*J35,0) -> 0
A36: INV-00326 | B36: 45669 | C36: P024 | D36: Sale | E36: -10 | F36: =E36 -> -10 | G36: South Warehouse | H36: CalcPlus | I36: China | J36: 6 | K36: 14 | M36: =ABS(E36)*J36 -> 60 | N36: =IF(Table1[[#This Row],[Transaction Type]]="Sale",ABS(E36)*K36,0) -> 140 | O36: =IF(Table1[[#This Row],[Transaction Type]]="Purchase",E36*J36,0) -> 0
A37: INV-00006 | B37: 45670 | C37: P005 | D37: Sale | E37: -14 | F37: =E37 -> -14 | G37: North Warehouse | H37: VisionTech | I37: China | J37: 18.5 | K37: 31 | M37: =ABS(E37)*J37 -> 259 | N37: =IF(Table1[[#This Row],[Transaction Type]]="Sale",ABS(E37)*K37,0) -> 434 | O37: =IF(Table1[[#This Row],[Transaction Type]]="Purchase",E37*J37,0) -> 0
A38: INV-01366 | B38: 45670 | C38: P004 | D38: Sale | E38: -7 | F38: =E38 -> -7 | G38: North Warehouse | H38: SoundMax | I38: Vietnam | J38: 20 | K38: 35 | M38: =ABS(E38)*J38 -> 140 | N38: =IF(Table1[[#This Row],[Transaction Type]]="Sale",ABS(E38)*K38,0) -> 245 | O38: =IF(Table1[[#This Row],[Transaction Type]]="Purchase",E38*J38,0) -> 0
A39: INV-00425 | B39: 45670 | C39: P002 | D39: Purchase | E39: 54 | F39: =E39 -> 54 | G39: Central Warehouse | H39: KeyPro | I39: China | J39: 25 | K39: 42 | L39: PO-17887 | M39: =ABS(E39)*J39 -> 1350 | N39: =IF(Table1[[#This Row],[Transaction Type]]="Sale",ABS(E39)*K39,0) -> 0 | O39: =IF(Table1[[#This Row],[Transaction Type]]="Purchase",E39*J39,0) -> 1350
A40: INV-00153 | B40: 45670 | C40: P004 | D40: Sale | E40: -8 | F40: =E40 -> -8 | G40: Central Warehouse | H40: SoundMax | I40: Vietnam | J40: 20 | K40: 35 | M40: =ABS(E40)*J40 -> 160 | N40: =IF(Table1[[#This Row],[Transaction Type]]="Sale",ABS(E40)*K40,0) -> 280 | O40: =IF(Table1[[#This Row],[Transaction Type]]="Purchase",E40*J40,0) -> 0
...

Sheet Dashboard

Sheet PivotTables
A2: Current Stock by Category | D2: Inventory Value by Supplier | G2: Units Purchased vs Sold by Category | K2: Products by Current Stock
A4: Row Labels | B4: Sum of Current Stock | D4: Row Labels | E4: Sum of Inventory Value | G4: Row Labels | H4: Sum of Total Purchased | I4: Sum of Total Sold | K4: Row Labels | L4: Sum of Current Stock
A5: Accessories | B5: 3163 | D5: WriteWell | E5: 8615.6 | G5: Accessories | H5: 3646 | I5: 533 | K5: Packing Tape | L5: 2562
A6: Electronics | B6: 14858 | D6: CalcPlus | E6: 10806 | G6: Electronics | H6: 18174 | I6: 3321 | K6: Mechanical Keyboard | L6: 2343
A7: Furniture | B7: 552 | D7: TechGear | E7: 18540 | G7: Furniture | H7: 859 | I7: 295 | K7: Shipping Labels | L7: 1923
A8: Office Supplies | B8: 4088 | D8: PaperMate | E8: 18543 | G8: Office Supplies | H8: 5381 | I8: 1341 | K8: Storage Bin | L8: 1795
A9: Packaging | B9: 4485 | D9: HydroLife | E9: 19397 | G9: Packaging | H9: 5532 | I9: 1024 | K9: File Folder Pack | L9: 1786
A10: Stationery | B10: 5630 | D10: PackRight | E10: 23072 | G10: Stationery | H10: 6952 | I10: 1428 | K10: Gel Pen Set | L10: 1762
A11: Warehouse | B11: 1795 | D11: VisionTech | E11: 24235 | G11: Warehouse | H11: 2087 | I11: 286 | K11: Wireless Mouse | L11: 1733
A12: Grand Total | B12: 34571 | D12: BrightHome | E12: 24570 | G12: Grand Total | H12: 42631 | I12: 8228 | K12: Bluetooth Speaker | L12: 1591
D13: StoreMax | E13: 26411 | K13: Water Bottle | L13: 1582
D14: VoltPro | E14: 32292 | K14: Backpack | L14: 1581
A15: Stock Status | D15: ConnectX | E15: 35842.5 | G15: Current Stock by Warehouse | K15: Grand Total | L15: 18658
D16: DeskWorks | E16: 39597.6
A17: Row Labels | B17: Count of Product ID | D17: TravelPro | E17: 50675 | G17: Row Labels | H17: Sum of Stock Movement
A18: Healthy Stock | B18: 30 | D18: ScanPro | E18: 60060 | G18: Central Warehouse | H18: 17372
A19: Grand Total | B19: 30 | D19: DataStore | E19: 67589.8 | G19: North Warehouse | H19: 9505
D20: KeyPro | E20: 71875 | G20: South Warehouse | H20: 7410
D21: ComfortPro | E21: 82320 | G21: Unknown | H21: 284
D22: ErgoSpace | E22: 84040 | G22: Grand Total | H22: 34571
D23: SoundMax | E23: 106056
D24: ViewPlus | E24: 161850
D25: PrintTech | E25: 190002
D26: Grand Total | E26: 1156389.5

Sheet Inventory Summary
A1: Product ID | B1: Product Name | C1: Category | D1: Supplier | E1: Reorder Level | F1: Safety Stock | G1: Lead Time Days | H1: Total Purchased | I1: Total Sold | J1: Total Returned | K1: Net Stock Movement | L1: Inventory Value | M1: Sales Value | N1: Stock Status | O1: Reorder Priority | P1: Current Stock
A2: P001 | B2: Wireless Mouse | C2: Electronics | D2: TechGear | E2: 180 | F2: 60 | G2: 14 | H2: =SUMIFS('Cleaned Inventory Data'!$E:$E,'Cleaned Inventory Data'!$C:$C,A2,'Cleaned Inventory Data'!$D:$D,"Purchase") -> 2117 | I2: =ABS(SUMIFS('Cleaned Inventory Data'!$E:$E,'Cleaned Inventory Data'!$C:$C,A2,'Cleaned Inventory Data'!$D:$D,"Sale")) -> 383 | J2: =SUMIFS('Cleaned Inventory Data'!$E:$E,'Cleaned Inventory Data'!$C:$C,A2,'Cleaned Inventory Data'!$D:$D,"Return") -> 10 | K2: =SUMIFS('Cleaned Inventory Data'!$F:$F,'Cleaned Inventory Data'!$C:$C,A2) -> 1733 | L2: =SUMIFS('Cleaned Inventory Data'!$M:$M,'Cleaned Inventory Data'!$C:$C,A2) -> 18540 | M2: =SUMIFS('Cleaned Inventory Data'!$N:$N,'Cleaned Inventory Data'!$C:$C,A2) -> 4787.5 | N2: =IF(K2<=F2,"Reorder Required",IF(K2<=E2,"Low Stock","Healthy Stock")) -> Healthy Stock | O2: =IF(K2<=F2,"High",IF(K2<=E2,"Medium","Low")) -> Low | P2: =K2 -> 1733
A3: P002 | B3: Mechanical Keyboard | C3: Electronics | D3: KeyPro | E3: 120 | F3: 40 | G3: 21 | H3: =SUMIFS('Cleaned Inventory Data'!$E:$E,'Cleaned Inventory Data'!$C:$C,A3,'Cleaned Inventory Data'!$D:$D,"Purchase") -> 2586 | I3: =ABS(SUMIFS('Cleaned Inventory Data'!$E:$E,'Cleaned Inventory Data'!$C:$C,A3,'Cleaned Inventory Data'!$D:$D,"Sale")) -> 258 | J3: =SUMIFS('Cleaned Inventory Data'!$E:$E,'Cleaned Inventory Data'!$C:$C,A3,'Cleaned Inventory Data'!$D:$D,"Return") -> 23 | K3: =SUMIFS('Cleaned Inventory Data'!$F:$F,'Cleaned Inventory Data'!$C:$C,A3) -> 2343 | L3: =SUMIFS('Cleaned Inventory Data'!$M:$M,'Cleaned Inventory Data'!$C:$C,A3) -> 71875 | M3: =SUMIFS('Cleaned Inventory Data'!$N:$N,'Cleaned Inventory Data'!$C:$C,A3) -> 10836 | N3: =IF(K3<=F3,"Reorder Required",IF(K3<=E3,"Low Stock","Healthy Stock")) -> Healthy Stock | O3: =IF(K3<=F3,"High",IF(K3<=E3,"Medium","Low")) -> Low | P3: =K3 -> 2343
A4: P003 | B4: USB-C Hub | C4: Electronics | D4: ConnectX | E4: 150 | F4: 50 | G4: 18 | H4: =SUMIFS('Cleaned Inventory Data'!$E:$E,'Cleaned Inventory Data'!$C:$C,A4,'Cleaned Inventory Data'!$D:$D,"Purchase") -> 1234 | I4: =ABS(SUMIFS('Cleaned Inventory Data'!$E:$E,'Cleaned Inventory Data'!$C:$C,A4,'Cleaned Inventory Data'!$D:$D,"Sale")) -> 338 | J4: =SUMIFS('Cleaned Inventory Data'!$E:$E,'Cleaned Inventory Data'!$C:$C,A4,'Cleaned Inventory Data'!$D:$D,"Return") -> 8 | K4: =SUMIFS('Cleaned Inventory Data'!$F:$F,'Cleaned Inventory Data'!$C:$C,A4) -> 873 | L4: =SUMIFS('Cleaned Inventory Data'!$M:$M,'Cleaned Inventory Data'!$C:$C,A4) -> 27274.5 | M4: =SUMIFS('Cleaned Inventory Data'!$N:$N,'Cleaned Inventory Data'!$C:$C,A4) -> 9464 | N4: =IF(K4<=F4,"Reorder Required",IF(K4<=E4,"Low Stock","Healthy Stock")) -> Healthy Stock | O4: =IF(K4<=F4,"High",IF(K4<=E4,"Medium","Low")) -> Low | P4: =K4 -> 873
A5: P004 | B5: Bluetooth Speaker | C5: Electronics | D5: SoundMax | E5: 100 | F5: 30 | G5: 20 | H5: =SUMIFS('Cleaned Inventory Data'!$E:$E,'Cleaned Inventory Data'!$C:$C,A5,'Cleaned Inventory Data'!$D:$D,"Purchase") -> 1875 | I5: =ABS(SUMIFS('Cleaned Inventory Data'!$E:$E,'Cleaned Inventory Data'!$C:$C,A5,'Cleaned Inventory Data'!$D:$D,"Sale")) -> 273 | J5: =SUMIFS('Cleaned Inventory Data'!$E:$E,'Cleaned Inventory Data'!$C:$C,A5,'Cleaned Inventory Data'!$D:$D,"Return") -> 2 | K5: =SUMIFS('Cleaned Inventory Data'!$F:$F,'Cleaned Inventory Data'!$C:$C,A5) -> 1591 | L5: =SUMIFS('Cleaned Inventory Data'!$M:$M,'Cleaned Inventory Data'!$C:$C,A5) -> 43700 | M5: =SUMIFS('Cleaned Inventory Data'!$N:$N,'Cleaned Inventory Data'!$C:$C,A5) -> 9555 | N5: =IF(K5<=F5,"Reorder Required",IF(K5<=E5,"Low Stock","Healthy Stock")) -> Healthy Stock | O5: =IF(K5<=F5,"High",IF(K5<=E5,"Medium","Low")) -> Low | P5: =K5 -> 1591
A6: P005 | B6: Webcam HD | C6: Electronics | D6: VisionTech | E6: 90 | F6: 30 | G6: 21 | H6: =SUMIFS('Cleaned Inventory Data'!$E:$E,'Cleaned Inventory Data'!$C:$C,A6,'Cleaned Inventory Data'!$D:$D,"Purchase") -> 972 | I6: =ABS(SUMIFS('Cleaned Inventory Data'!$E:$E,'Cleaned Inventory Data'!$C:$C,A6,'Cleaned Inventory Data'!$D:$D,"Sale")) -> 249 | J6: =SUMIFS('Cleaned Inventory Data'!$E:$E,'Cleaned Inventory Data'!$C:$C,A6,'Cleaned Inventory Data'!$D:$D,"Return") -> 4 | K6: =SUMIFS('Cleaned Inventory Data'!$F:$F,'Cleaned Inventory Data'!$C:$C,A6) -> 694 | L6: =SUMIFS('Cleaned Inventory Data'!$M:$M,'Cleaned Inventory Data'!$C:$C,A6) -> 24235 | M6: =SUMIFS('Cleaned Inventory Data'!$N:$N,'Cleaned Inventory Data'!$C:$C,A6) -> 7719 | N6: =IF(K6<=F6,"Reorder Required",IF(K6<=E6,"Low Stock","Healthy Stock")) -> Healthy Stock | O6: =IF(K6<=F6,"High",IF(K6<=E6,"Medium","Low")) -> Low | P6: =K6 -> 694
A7: P006 | B7: 27-inch Monitor | C7: Electronics | D7: ViewPlus | E7: 70 | F7: 20 | G7: 30 | H7: =SUMIFS('Cleaned Inventory Data'!$E:$E,'Cleaned Inventory Data'!$C:$C,A7,'Cleaned Inventory Data'!$D:$D,"Purchase") -> 1038 | I7: =ABS(SUMIFS('Cleaned Inventory Data'!$E:$E,'Cleaned Inventory Data'!$C:$C,A7,'Cleaned Inventory Data'!$D:$D,"Sale")) -> 194 | J7: =SUMIFS('Cleaned Inventory Data'!$E:$E,'Cleaned Inventory Data'!$C:$C,A7,'Cleaned Inventory Data'!$D:$D,"Return") -> 2 | K7: =SUMIFS('Cleaned Inventory Data'!$F:$F,'Cleaned Inventory Data'!$C:$C,A7) -> 857 | L7: =SUMIFS('Cleaned Inventory Data'!$M:$M,'Cleaned Inventory Data'!$C:$C,A7) -> 161850 | M7: =SUMIFS('Cleaned Inventory Data'!$N:$N,'Cleaned Inventory Data'!$C:$C,A7) -> 35890 | N7: =IF(K7<=F7,"Reorder Required",IF(K7<=E7,"Low Stock","Healthy Stock")) -> Healthy Stock | O7: =IF(K7<=F7,"High",IF(K7<=E7,"Medium","Low")) -> Low | P7: =K7 -> 857
A8: P007 | B8: Laptop Stand | C8: Office Supplies | D8: DeskWorks | E8: 110 | F8: 35 | G8: 18 | H8: =SUMIFS('Cleaned Inventory Data'!$E:$E,'Cleaned Inventory Data'!$C:$C,A8,'Cleaned Inventory Data'!$D:$D,"Purchase") -> 1056 | I8: =ABS(SUMIFS('Cleaned Inventory Data'!$E:$E,'Cleaned Inventory Data'!$C:$C,A8,'Cleaned Inventory Data'!$D:$D,"Sale")) -> 262 | J8: =SUMIFS('Cleaned Inventory Data'!$E:$E,'Cleaned Inventory Data'!$C:$C,A8,'Cleaned Inventory Data'!$D:$D,"Return") -> 0 | K8: =SUMIFS('Cleaned Inventory Data'!$F:$F,'Cleaned Inventory Data'!$C:$C,A8) -> 794 | L8: =SUMIFS('Cleaned Inventory Data'!$M:$M,'Cleaned Inventory Data'!$C:$C,A8) -> 21088 | M8: =SUMIFS('Cleaned Inventory Data'!$N:$N,'Cleaned Inventory Data'!$C:$C,A8) -> 7598 | N8: =IF(K8<=F8,"Reorder Required",IF(K8<=E8,"Low Stock","Healthy Stock")) -> Healthy Stock | O8: =IF(K8<=F8,"High",IF(K8<=E8,"Medium","Low")) -> Low | P8: =K8 -> 794
A9: P008 | B9: Desk Lamp | C9: Office Supplies | D9: BrightHome | E9: 100 | F9: 30 | G9: 15 | H9: =SUMIFS('Cleaned Inventory Data'!$E:$E,'Cleaned Inventory Data'!$C:$C,A9,'Cleaned Inventory Data'!$D:$D,"Purchase") -> 1419 | I9: =ABS(SUMIFS('Cleaned Inventory Data'!$E:$E,'Cleaned Inventory Data'!$C:$C,A9,'Cleaned Inventory Data'!$D:$D,"Sale")) -> 321 | J9: =SUMIFS('Cleaned Inventory Data'!$E:$E,'Cleaned Inventory Data'!$C:$C,A9,'Cleaned Inventory Data'!$D:$D,"Return") -> 7 | K9: =SUMIFS('Cleaned Inventory Data'!$F:$F,'Cleaned Inventory Data'!$C:$C,A9) -> 1090 | L9: =SUMIFS('Cleaned Inventory Data'!$M:$M,'Cleaned Inventory Data'!$C:$C,A9) -> 24570 | M9: =SUMIFS('Cleaned Inventory Data'!$N:$N,'Cleaned Inventory Data'!$C:$C,A9) -> 7704 | N9: =IF(K9<=F9,"Reorder Required",IF(K9<=E9,"Low Stock","Healthy Stock")) -> Healthy Stock | O9: =IF(K9<=F9,"High",IF(K9<=E9,"Medium","Low")) -> Low | P9: =K9 -> 1090
A10: P009 | B10: Office Chair | C10: Furniture | D10: ComfortPro | E10: 45 | F10: 15 | G10: 30 | H10: =SUMIFS('Cleaned Inventory Data'!$E:$E,'Cleaned Inventory Data'!$C:$C,A10,'Cleaned Inventory Data'!$D:$D,"Purchase") -> 607 | I10: =ABS(SUMIFS('Cleaned Inventory Data'!$E:$E,'Cleaned Inventory Data'!$C:$C,A10,'Cleaned Inventory Data'!$D:$D,"Sale")) -> 172 | J10: =SUMIFS('Cleaned Inventory Data'!$E:$E,'Cleaned Inventory Data'!$C:$C,A10,'Cleaned Inventory Data'!$D:$D,"Return") -> 0 | K10: =SUMIFS('Cleaned Inventory Data'!$F:$F,'Cleaned Inventory Data'!$C:$C,A10) -> 430 | L10: =SUMIFS('Cleaned Inventory Data'!$M:$M,'Cleaned Inventory Data'!$C:$C,A10) -> 82320 | M10: =SUMIFS('Cleaned Inventory Data'!$N:$N,'Cleaned Inventory Data'!$C:$C,A10) -> 28380 | N10: =IF(K10<=F10,"Reorder Required",IF(K10<=E10,"Low Stock","Healthy Stock")) -> Healthy Stock | O10: =IF(K10<=F10,"High",IF(K10<=E10,"Medium","Low")) -> Low | P10: =K10 -> 430
A11: P010 | B11: Standing Desk | C11: Furniture | D11: ErgoSpace | E11: 30 | F11: 10 | G11: 45 | H11: =SUMIFS('Cleaned Inventory Data'!$E:$E,'Cleaned Inventory Data'!$C:$C,A11,'Cleaned Inventory Data'!$D:$D,"Purchase") -> 252 | I11: =ABS(SUMIFS('Cleaned Inventory Data'!$E:$E,'Cleaned Inventory Data'!$C:$C,A11,'Cleaned Inventory Data'!$D:$D,"Sale")) -> 123 | J11: =SUMIFS('Cleaned Inventory Data'!$E:$E,'Cleaned Inventory Data'!$C:$C,A11,'Cleaned Inventory Data'!$D:$D,"Return") -> 0 | K11: =SUMIFS('Cleaned Inventory Data'!$F:$F,'Cleaned Inventory Data'!$C:$C,A11) -> 122 | L11: =SUMIFS('Cleaned Inventory Data'!$M:$M,'Cleaned Inventory Data'!$C:$C,A11) -> 84040 | M11: =SUMIFS('Cleaned Inventory Data'!$N:$N,'Cleaned Inventory Data'!$C:$C,A11) -> 39360 | N11: =IF(K11<=F11,"Reorder Required",IF(K11<=E11,"Low Stock","Healthy Stock")) -> Healthy Stock | O11: =IF(K11<=F11,"High",IF(K11<=E11,"Medium","Low")) -> Low | P11: =K11 -> 122
A12: P011 | B12: Notebook A5 | C12: Stationery | D12: PaperMate | E12: 300 | F12: 100 | G12: 10 | H12: =SUMIFS('Cleaned Inventory Data'!$E:$E,'Cleaned Inventory Data'!$C:$C,A12,'Cleaned Inventory Data'!$D:$D,"Purchase") -> 1322 | I12: =ABS(SUMIFS('Cleaned Inventory Data'!$E:$E,'Cleaned Inventory Data'!$C:$C,A12,'Cleaned Inventory Data'!$D:$D,"Sale")) -> 375 | J12: =SUMIFS('Cleaned Inventory Data'!$E:$E,'Cleaned Inventory Data'!$C:$C,A12,'Cleaned Inventory Data'!$D:$D,"Return") -> 6 | K12: =SUMIFS('Cleaned Inventory Data'!$F:$F,'Cleaned Inventory Data'!$C:$C,A12) -> 941 | L12: =SUMIFS('Cleaned Inventory Data'!$M:$M,'Cleaned Inventory Data'!$C:$C,A12) -> 4485 | M12: =SUMIFS('Cleaned Inventory Data'!$N:$N,'Cleaned Inventory Data'!$C:$C,A12) -> 2062.5 | N12: =IF(K12<=F12,"Reorder Required",IF(K12<=E12,"Low Stock","Healthy Stock")) -> Healthy Stock | O12: =IF(K12<=F12,"High",IF(K12<=E12,"Medium","Low")) -> Low | P12: =K12 -> 941
A13: P012 | B13: Gel Pen Set | C13: Stationery | D13: WriteWell | E13: 250 | F13: 80 | G13: 10 | H13: =SUMIFS('Cleaned Inventory Data'!$E:$E,'Cleaned Inventory Data'!$C:$C,A13,'Cleaned Inventory Data'!$D:$D,"Purchase") -> 2081 | I13: =ABS(SUMIFS('Cleaned Inventory Data'!$E:$E,'Cleaned Inventory Data'!$C:$C,A13,'Cleaned Inventory Data'!$D:$D,"Sale")) -> 366 | J13: =SUMIFS('Cleaned Inventory Data'!$E:$E,'Cleaned Inventory Data'!$C:$C,A13,'Cleaned Inventory Data'!$D:$D,"Return") -> 8 | K13: =SUMIFS('Cleaned Inventory Data'!$F:$F,'Cleaned Inventory Data'!$C:$C,A13) -> 1762 | L13: =SUMIFS('Cleaned Inventory Data'!$M:$M,'Cleaned Inventory Data'!$C:$C,A13) -> 8615.6 | M13: =SUMIFS('Cleaned Inventory Data'!$N:$N,'Cleaned Inventory Data'!$C:$C,A13) -> 2928 | N13: =IF(K13<=F13,"Reorder Required",IF(K13<=E13,"Low Stock","Healthy Stock")) -> Healthy Stock | O13: =IF(K13<=F13,"High",IF(K13<=E13,"Medium","Low")) -> Low | P13: =K13 -> 1762
... A31: P030 | B31: Storage Bin | C31: Warehouse | D31: StoreMax | E31: 180 | F31: 60 | G31: 14 | H31: =SUMIFS('Cleaned Inventory Data'!$E:$E,'Cleaned Inventory Data'!$C:$C,A31,'Cleaned Inventory Data'!$D:$D,"Purchase") -> 2087 | I31: =ABS(SUMIFS('Cleaned Inventory Data'!$E:$E,'Cleaned Inventory Data'!$C:$C,A31,'Cleaned Inventory Data'!$D:$D,"Sale")) -> 286 | J31: =SUMIFS('Cleaned Inventory Data'!$E:$E,'Cleaned Inventory Data'!$C:$C,A31,'Cleaned Inventory Data'!$D:$D,"Return") -> 11 | K31: =SUMIFS('Cleaned Inventory Data'!$F:$F,'Cleaned Inventory Data'!$C:$C,A31) -> 1795 | L31: =SUMIFS('Cleaned Inventory Data'!$M:$M,'Cleaned Inventory Data'!$C:$C,A31) -> 26411 | M31: =SUMIFS('Cleaned Inventory Data'!$N:$N,'Cleaned Inventory Data'!$C:$C,A31) -> 6292 | N31: =IF(K31<=F31,"Reorder Required",IF(K31<=E31,"Low Stock","Healthy Stock")) -> Healthy Stock | O31: =IF(K31<=F31,"High",IF(K31<=E31,"Medium","Low")) -> Low | P31: =K31 -> 1795

Sheet KPI Summary
A1: Total Products | B1: =COUNTA('Inventory Summary'!A2:A31) -> 30
A2: Total Current Stock | B2: =SUM('Inventory Summary'!P2:P31) -> 34571
A3: Total Inventory Value | B3: =SUM('Inventory Summary'!L2:L31) -> 1156389.5
A4: Total Units Purchased | B4: =SUM('Inventory Summary'!H2:H31) -> 42631
A5: Total Units Sold | B5: =SUM('Inventory Summary'!I2:I31) -> 8228
A6: Total Units Returned | B6: =SUM('Inventory Summary'!J2:J31) -> 206
A7: Low Stock Items | B7: =COUNTIF('Inventory Summary'!N2:N31,"Low Stock") -> 0
A8: Reorder Required Items | B8: =COUNTIF('Inventory Summary'!N2:N31,"Reorder Required") -> 0

Sheet Data Quality Log
A1: Issue | B1: Count | C1: Action | D1: Reason
A2: Exact duplicates | B2: 23 | C2: Removed | D2: Duplicate transaction records
A3: Missing Quantity | B3: 4 | C3: Removed | D3: Required for inventory movement
A4: Zero Quantity | B4: 4 | C4: Removed | D4: No inventory movement
A5: Missing Warehouse | B5: 15 | C5: Set to Unknown | D5: Cannot reliably infer warehouse
A6: Missing Supplier | B6: 13 | C6: Recovered | D6: Matched using Product Master
A7: Missing Unit Cost | B7: 10 | C7: Recovered | D7: Matched using Product Master
A8: Missing Unit Price | B8: 8 | C8: Recovered | D8: Matched using Product Master
A9: Blank Purchase Order | B9: 1202 | C9: Kept | D9: Expected for non-purchase transactions
